[
    {
        "content": "<p>Somehow bors failed on <a href=\"https://github.com/leanprover-community/mathlib4/pull/9558\">#9558</a> with an internal server error after <span class=\"user-mention\" data-user-id=\"459699\">@JoÃ«l Riou</span> did <code>bors merge</code>. I tried rerunning the job, but it either gets cancelled by some github action or suceeds but still says \"cancelled\". Can someone trigger a new try or do I need to do something?</p>",
        "id": 412023069,
        "sender_full_name": "Christian Merten",
        "timestamp": 1704839496
    },
    {
        "content": "<p><span class=\"user-group-mention\" data-user-group-id=\"2494\">@maintainers</span></p>",
        "id": 412023108,
        "sender_full_name": "Ruben Van de Velde",
        "timestamp": 1704839521
    },
    {
        "content": "<p><span class=\"user-mention silent\" data-user-id=\"648495\">Christian Merten</span> has marked this topic as resolved.</p>",
        "id": 412028788,
        "sender_full_name": "Notification Bot",
        "timestamp": 1704842512
    }
]